Workbook

Sheet Executive Dashboard
B2: Zupp1 — 30-Day Revenue Tracking Dashboard
B3: Source plan: MQ-REV-01 — 30-Day Revenue and Six-Month Reinvestment Plan
B4: Daily budget R$20 · 30-day ceiling R$600 · Stated contribution margin 10% · Break-even ROAS 10.0x · Geography: São Paulo state
B5: Break-even ROAS = 1 ÷ contribution margin = 1 ÷ 10% = 10.0x, BEFORE excluded variable costs (refunds, chargebacks, shipping subsidies, payment fees, taxes). Any excluded cost raises the true break-even above 10.0x. Month 1 objective: first attributable revenue and credible repeatability — not clicks.
B7: MONTH SPEND vs R$600 CEILING | D7: SETTLED ATTRIBUTED REVENUE | F7: MARKETING PROFIT (MONTH) | H7: BLENDED ROAS vs 10.0x BREAK-EVEN | J7: REINVESTMENT WALLET
B8: ='Weekly Summary'!$H$8 -> 0 | D8: ='Weekly Summary'!$H$11 -> 0 | F8: =IF('Weekly Summary'!$H$21="","",'Weekly Summary'!$H$21) | H8: =IF('Weekly Summary'!$H$20="","",'Weekly Summary'!$H$20) | J8: =IF('Weekly Summary'!$H$22="","",'Weekly Summary'!$H$22)
B10: =IF(N('Weekly Summary'!$H$8)=0,"No spend recorded · ceiling R$600","Remaining: "&TEXT('Daily Input'!$I$3-N('Weekly Summary'!$H$8),"""R$"" #,##0.00")) -> No spend recorded · ceiling R$600 | D10: =IF(N('Weekly Summary'!$H$11)=0,"No settled revenue yet","Fulfilled orders: "&TEXT(N('Weekly Summary'!$H$13),"#,##0")) -> No settled revenue yet | F10: =IF('Weekly Summary'!$H$21="","Reinvestment permitted only on positive verified profit",IF('Weekly Summary'!$H$21>0,"Positive — reinvestment may be released","Negative — automatic reinvestment stops")) -> Reinvestment permitted only on positive verified profit | H10: =IF('Weekly Summary'!$H$20="","No spend recorded",IF('Weekly Summary'!$H$20>='Weekly Summary'!$E$3,"At or above break-even","Below the 10.0x break-even threshold")) -> No spend recorded | J10: =IF(N('Weekly Summary'!$H$22)=0,"Nothing verified for release","Recovered principal + verified profit") -> Nothing verified for release
B12: WEEKLY BRIDGE — the ten reportable lines
B13: Metric | C13: Week 1 · Days 1–7 | D13: Week 2 · Days 8–14 | E13: Week 3 · Days 15–21 | F13: Week 4 · Days 22–28 | G13: Closeout · Days 29–30 | H13: Month Total
B14: Spend (R$) | C14: ='Weekly Summary'!C8 -> 0 | D14: ='Weekly Summary'!D8 -> 0 | E14: ='Weekly Summary'!E8 -> 0 | F14: ='Weekly Summary'!F8 -> 0 | G14: ='Weekly Summary'!G8 -> 0 | H14: ='Weekly Summary'!H8 -> 0
B15: Settled Attributed Revenue (R$) | C15: ='Weekly Summary'!C11 -> 0 | D15: ='Weekly Summary'!D11 -> 0 | E15: ='Weekly Summary'!E11 -> 0 | F15: ='Weekly Summary'!F11 -> 0 | G15: ='Weekly Summary'!G11 -> 0 | H15: ='Weekly Summary'!H11 -> 0
B16: Fulfilled Attributed Orders | C16: ='Weekly Summary'!C13 -> 0 | D16: ='Weekly Summary'!D13 -> 0 | E16: ='Weekly Summary'!E13 -> 0 | F16: ='Weekly Summary'!F13 -> 0 | G16: ='Weekly Summary'!G13 -> 0 | H16: ='Weekly Summary'!H13 -> 0
B17: AOV (R$) | C17: ='Weekly Summary'!C14 | D17: ='Weekly Summary'!D14 | E17: ='Weekly Summary'!E14 | F17: ='Weekly Summary'!F14 | G17: ='Weekly Summary'!G14 | H17: ='Weekly Summary'!H14
B18: Verified Contribution Margin (%) | C18: ='Weekly Summary'!C15 | D18: ='Weekly Summary'!D15 | E18: ='Weekly Summary'!E15 | F18: ='Weekly Summary'!F15 | G18: ='Weekly Summary'!G15 | H18: ='Weekly Summary'!H15
B19: Contribution (R$) | C19: ='Weekly Summary'!C16 -> 0 | D19: ='Weekly Summary'!D16 -> 0 | E19: ='Weekly Summary'!E16 -> 0 | F19: ='Weekly Summary'!F16 -> 0 | G19: ='Weekly Summary'!G16 -> 0 | H19: ='Weekly Summary'!H16 -> 0
B20: CPA (R$) | C20: ='Weekly Summary'!C18 | D20: ='Weekly Summary'!D18 | E20: ='Weekly Summary'!E18 | F20: ='Weekly Summary'!F18 | G20: ='Weekly Summary'!G18 | H20: ='Weekly Summary'!H18
B21: Maximum Allowable CAC (R$) | C21: ='Weekly Summary'!C19 | D21: ='Weekly Summary'!D19 | E21: ='Weekly Summary'!E19 | F21: ='Weekly Summary'!F19 | G21: ='Weekly Summary'!G19 | H21: ='Weekly Summary'!H19
B22: Blended ROAS (x) · break-even 10.0x | C22: ='Weekly Summary'!C20 | D22: ='Weekly Summary'!D20 | E22: ='Weekly Summary'!E20 | F22: ='Weekly Summary'!F20 | G22: ='Weekly Summary'!G20 | H22: ='Weekly Summary'!H20
B23: Marketing Profit (R$) | C23: ='Weekly Summary'!C21 | D23: ='Weekly Summary'!D21 | E23: ='Weekly Summary'!E21 | F23: ='Weekly Summary'!F21 | G23: ='Weekly Summary'!G21 | H23: ='Weekly Summary'!H21
B24: Reinvestment Wallet (R$) | C24: ='Weekly Summary'!C22 | D24: ='Weekly Summary'!D22 | E24: ='Weekly Summary'!E22 | F24: ='Weekly Summary'!F22 | G24: ='Weekly Summary'!G22 | H24: ='Weekly Summary'!H22
B25: Largest Funnel Bottleneck | C25: ='Weekly Summary'!C41 -> N/A | D25: ='Weekly Summary'!D41 -> N/A | E25: ='Weekly Summary'!E41 -> N/A | F25: ='Weekly Summary'!F41 -> N/A | G25: ='Weekly Summary'!G41 -> N/A | H25: ='Weekly Summary'!H41 -> N/A
B26: Decision | C26: ='Weekly Summary'!C43 -> HOLD / INSUFFICIENT DATA | D26: ='Weekly Summary'!D43 -> HOLD / INSUFFICIENT DATA | E26: ='Weekly Summary'!E43 -> HOLD / INSUFFICIENT DATA | F26: ='Weekly Summary'!F43 -> HOLD / INSUFFICIENT DATA | G26: ='Weekly Summary'!G43 -> HOLD / INSUFFICIENT DATA | H26: ='Weekly Summary'!H43 -> HOLD / INSUFFICIENT DATA
B27: Status | C27: ='Weekly Summary'!C44 -> NO DATA | D27: ='Weekly Summary'!D44 -> NO DATA | E27: ='Weekly Summary'!E44 -> NO DATA | F27: ='Weekly Summary'!F44 -> NO DATA | G27: ='Weekly Summary'!G44 -> NO DATA | H27: ='Weekly Summary'!H44 -> NO DATA
B29: Blank cells mean no data has been recorded — they are not zeros. All values are live links to Weekly Summary, which aggregates raw Daily Input rows.
B30: INTELLIGENCE GAP: the exact cost basis of the 10% margin, product-level AOV and margin, shipping subsidy, refund, chargeback, payment-fee and tax assumptions, and the hero product remain unverified. Treat every derived economic figure as provisional until they are recorded.

Sheet Daily Input
B2: Daily Input — 30-Day Paid Media Ledger
B3: Campaign start date | C3: 46251 | D3: Default contribution margin | E3: 0.1 | F3: Daily budget cap (R$) | G3: 20 | H3: 30-day spend ceiling (R$) | I3: 600
B4: Enter observed data only. Blue cells are editable assumptions; black cells are formulas. Leave unknown values blank — never enter 0 unless zero was actually observed. Geography: São Paulo state. Objective: first attributable revenue and credible repeatability, not clicks.
B5: Date | C5: Week | D5: Campaign | E5: Ad Set | F5: Creative / Treatment | G5: Product / Family | H5: Spend (R$) | I5: Impressions | J5: Link Clicks | K5: Landing Page Views | L5: Product Views | M5: Add to Cart | N5: Checkout Initiations | O5: Attributed Orders | P5: Fulfilled Orders | Q5: Gross Attributed Revenue (R$) | R5: Cancellations / Refunds (R$) | S5: Settled Attributed Revenue (R$) | T5: Contribution Margin (%) | U5: Excluded Variable Costs (R$) | V5: Tracking Status | W5: Checkout Status | X5: Product Availability | Y5: Notes | Z5: CTR | AA5: CPC (R$) | AB5: LPV Rate | AC5: Product View Rate | AD5: ATC Rate | AE5: Checkout Rate | AF5: Purchase CVR | AG5: AOV (R$) | AH5: Contribution (R$) | AI5: CPA (R$) | AJ5: Max Allowable CAC (R$) | AK5: ROAS (x) | AL5: Marketing Profit (R$) | AM5: Reinvestment Wallet (R$)
B6: =IF($C$3="","",$C$3+0) -> 46251 | C6: =IF($B6="","",IF($B6-$C$3+1>28,"Closeout","Week "&ROUNDUP(($B6-$C$3+1)/7,0))) -> Week 1 | T6: =IF($E$3="","",$E$3) -> 0.1 | Z6: =IF(N($I6)=0,"",IFERROR($J6/$I6,"")) | AA6: =IF(N($J6)=0,"",IFERROR($H6/$J6,"")) | AB6: =IF(N($J6)=0,"",IFERROR($K6/$J6,"")) | AC6: =IF(N($K6)=0,"",IFERROR($L6/$K6,"")) | AD6: =IF(N($L6)=0,"",IFERROR($M6/$L6,"")) | AE6: =IF(N($M6)=0,"",IFERROR($N6/$M6,"")) | AF6: =IF(N($N6)=0,"",IFERROR($P6/$N6,"")) | AG6: =IF(N($P6)=0,"",IFERROR($S6/$P6,"")) | AH6: =IF($S6="","",$S6*N($T6)) | AI6: =IF(N($P6)=0,"",IFERROR($H6/$P6,"")) | AJ6: =IF($AG6="","",$AG6*N($T6)) | AK6: =IF(N($H6)=0,"",IFERROR($S6/$H6,"")) | AL6: =IF(AND($H6="",$S6=""),"",N($AH6)-N($H6)-N($U6)) | AM6: =IF($AL6="","",MAX(0,$AL6))
B7: =IF($C$3="","",$C$3+1) -> 46252 | C7: =IF($B7="","",IF($B7-$C$3+1>28,"Closeout","Week "&ROUNDUP(($B7-$C$3+1)/7,0))) -> Week 1 | T7: =IF($E$3="","",$E$3) -> 0.1 | Z7: =IF(N($I7)=0,"",IFERROR($J7/$I7,"")) | AA7: =IF(N($J7)=0,"",IFERROR($H7/$J7,"")) | AB7: =IF(N($J7)=0,"",IFERROR($K7/$J7,"")) | AC7: =IF(N($K7)=0,"",IFERROR($L7/$K7,"")) | AD7: =IF(N($L7)=0,"",IFERROR($M7/$L7,"")) | AE7: =IF(N($M7)=0,"",IFERROR($N7/$M7,"")) | AF7: =IF(N($N7)=0,"",IFERROR($P7/$N7,"")) | AG7: =IF(N($P7)=0,"",IFERROR($S7/$P7,"")) | AH7: =IF($S7="","",$S7*N($T7)) | AI7: =IF(N($P7)=0,"",IFERROR($H7/$P7,"")) | AJ7: =IF($AG7="","",$AG7*N($T7)) | AK7: =IF(N($H7)=0,"",IFERROR($S7/$H7,"")) | AL7: =IF(AND($H7="",$S7=""),"",N($AH7)-N($H7)-N($U7)) | AM7: =IF($AL7="","",MAX(0,$AL7))
B8: =IF($C$3="","",$C$3+2) -> 46253 | C8: =IF($B8="","",IF($B8-$C$3+1>28,"Closeout","Week "&ROUNDUP(($B8-$C$3+1)/7,0))) -> Week 1 | T8: =IF($E$3="","",$E$3) -> 0.1 | Z8: =IF(N($I8)=0,"",IFERROR($J8/$I8,"")) | AA8: =IF(N($J8)=0,"",IFERROR($H8/$J8,"")) | AB8: =IF(N($J8)=0,"",IFERROR($K8/$J8,"")) | AC8: =IF(N($K8)=0,"",IFERROR($L8/$K8,"")) | AD8: =IF(N($L8)=0,"",IFERROR($M8/$L8,"")) | AE8: =IF(N($M8)=0,"",IFERROR($N8/$M8,"")) | AF8: =IF(N($N8)=0,"",IFERROR($P8/$N8,"")) | AG8: =IF(N($P8)=0,"",IFERROR($S8/$P8,"")) | AH8: =IF($S8="","",$S8*N($T8)) | AI8: =IF(N($P8)=0,"",IFERROR($H8/$P8,"")) | AJ8: =IF($AG8="","",$AG8*N($T8)) | AK8: =IF(N($H8)=0,"",IFERROR($S8/$H8,"")) | AL8: =IF(AND($H8="",$S8=""),"",N($AH8)-N($H8)-N($U8)) | AM8: =IF($AL8="","",MAX(0,$AL8))
B9: =IF($C$3="","",$C$3+3) -> 46254 | C9: =IF($B9="","",IF($B9-$C$3+1>28,"Closeout","Week "&ROUNDUP(($B9-$C$3+1)/7,0))) -> Week 1 | T9: =IF($E$3="","",$E$3) -> 0.1 | Z9: =IF(N($I9)=0,"",IFERROR($J9/$I9,"")) | AA9: =IF(N($J9)=0,"",IFERROR($H9/$J9,"")) | AB9: =IF(N($J9)=0,"",IFERROR($K9/$J9,"")) | AC9: =IF(N($K9)=0,"",IFERROR($L9/$K9,"")) | AD9: =IF(N($L9)=0,"",IFERROR($M9/$L9,"")) | AE9: =IF(N($M9)=0,"",IFERROR($N9/$M9,"")) | AF9: =IF(N($N9)=0,"",IFERROR($P9/$N9,"")) | AG9: =IF(N($P9)=0,"",IFERROR($S9/$P9,"")) | AH9: =IF($S9="","",$S9*N($T9)) | AI9: =IF(N($P9)=0,"",IFERROR($H9/$P9,"")) | AJ9: =IF($AG9="","",$AG9*N($T9)) | AK9: =IF(N($H9)=0,"",IFERROR($S9/$H9,"")) | AL9: =IF(AND($H9="",$S9=""),"",N($AH9)-N($H9)-N($U9)) | AM9: =IF($AL9="","",MAX(0,$AL9))
B10: =IF($C$3="","",$C$3+4) -> 46255 | C10: =IF($B10="","",IF($B10-$C$3+1>28,"Closeout","Week "&ROUNDUP(($B10-$C$3+1)/7,0))) -> Week 1 | T10: =IF($E$3="","",$E$3) -> 0.1 | Z10: =IF(N($I10)=0,"",IFERROR($J10/$I10,"")) | AA10: =IF(N($J10)=0,"",IFERROR($H10/$J10,"")) | AB10: =IF(N($J10)=0,"",IFERROR($K10/$J10,"")) | AC10: =IF(N($K10)=0,"",IFERROR($L10/$K10,"")) | AD10: =IF(N($L10)=0,"",IFERROR($M10/$L10,"")) | AE10: =IF(N($M10)=0,"",IFERROR($N10/$M10,"")) | AF10: =IF(N($N10)=0,"",IFERROR($P10/$N10,"")) | AG10: =IF(N($P10)=0,"",IFERROR($S10/$P10,"")) | AH10: =IF($S10="","",$S10*N($T10)) | AI10: =IF(N($P10)=0,"",IFERROR($H10/$P10,"")) | AJ10: =IF($AG10="","",$AG10*N($T10)) | AK10: =IF(N($H10)=0,"",IFERROR($S10/$H10,"")) | AL10: =IF(AND($H10="",$S10=""),"",N($AH10)-N($H10)-N($U10)) | AM10: =IF($AL10="","",MAX(0,$AL10))
B11: =IF($C$3="","",$C$3+5) -> 46256 | C11: =IF($B11="","",IF($B11-$C$3+1>28,"Closeout","Week "&ROUNDUP(($B11-$C$3+1)/7,0))) -> Week 1 | T11: =IF($E$3="","",$E$3) -> 0.1 | Z11: =IF(N($I11)=0,"",IFERROR($J11/$I11,"")) | AA11: =IF(N($J11)=0,"",IFERROR($H11/$J11,"")) | AB11: =IF(N($J11)=0,"",IFERROR($K11/$J11,"")) | AC11: =IF(N($K11)=0,"",IFERROR($L11/$K11,"")) | AD11: =IF(N($L11)=0,"",IFERROR($M11/$L11,"")) | AE11: =IF(N($M11)=0,"",IFERROR($N11/$M11,"")) | AF11: =IF(N($N11)=0,"",IFERROR($P11/$N11,"")) | AG11: =IF(N($P11)=0,"",IFERROR($S11/$P11,"")) | AH11: =IF($S11="","",$S11*N($T11)) | AI11: =IF(N($P11)=0,"",IFERROR($H11/$P11,"")) | AJ11: =IF($AG11="","",$AG11*N($T11)) | AK11: =IF(N($H11)=0,"",IFERROR($S11/$H11,"")) | AL11: =IF(AND($H11="",$S11=""),"",N($AH11)-N($H11)-N($U11)) | AM11: =IF($AL11="","",MAX(0,$AL11))
B12: =IF($C$3="","",$C$3+6) -> 46257 | C12: =IF($B12="","",IF($B12-$C$3+1>28,"Closeout","Week "&ROUNDUP(($B12-$C$3+1)/7,0))) -> Week 1 | T12: =IF($E$3="","",$E$3) -> 0.1 | Z12: =IF(N($I12)=0,"",IFERROR($J12/$I12,"")) | AA12: =IF(N($J12)=0,"",IFERROR($H12/$J12,"")) | AB12: =IF(N($J12)=0,"",IFERROR($K12/$J12,"")) | AC12: =IF(N($K12)=0,"",IFERROR($L12/$K12,"")) | AD12: =IF(N($L12)=0,"",IFERROR($M12/$L12,"")) | AE12: =IF(N($M12)=0,"",IFERROR($N12/$M12,"")) | AF12: =IF(N($N12)=0,"",IFERROR($P12/$N12,"")) | AG12: =IF(N($P12)=0,"",IFERROR($S12/$P12,"")) | AH12: =IF($S12="","",$S12*N($T12)) | AI12: =IF(N($P12)=0,"",IFERROR($H12/$P12,"")) | AJ12: =IF($AG12="","",$AG12*N($T12)) | AK12: =IF(N($H12)=0,"",IFERROR($S12/$H12,"")) | AL12: =IF(AND($H12="",$S12=""),"",N($AH12)-N($H12)-N($U12)) | AM12: =IF($AL12="","",MAX(0,$AL12))
B13: =IF($C$3="","",$C$3+7) -> 46258 | C13: =IF($B13="","",IF($B13-$C$3+1>28,"Closeout","Week "&ROUNDUP(($B13-$C$3+1)/7,0))) -> Week 2 | T13: =IF($E$3="","",$E$3) -> 0.1 | Z13: =IF(N($I13)=0,"",IFERROR($J13/$I13,"")) | AA13: =IF(N($J13)=0,"",IFERROR($H13/$J13,"")) | AB13: =IF(N($J13)=0,"",IFERROR($K13/$J13,"")) | AC13: =IF(N($K13)=0,"",IFERROR($L13/$K13,"")) | AD13: =IF(N($L13)=0,"",IFERROR($M13/$L13,"")) | AE13: =IF(N($M13)=0,"",IFERROR($N13/$M13,"")) | AF13: =IF(N($N13)=0,"",IFERROR($P13/$N13,"")) | AG13: =IF(N($P13)=0,"",IFERROR($S13/$P13,"")) | AH13: =IF($S13="","",$S13*N($T13)) | AI13: =IF(N($P13)=0,"",IFERROR($H13/$P13,"")) | AJ13: =IF($AG13="","",$AG13*N($T13)) | AK13: =IF(N($H13)=0,"",IFERROR($S13/$H13,"")) | AL13: =IF(AND($H13="",$S13=""),"",N($AH13)-N($H13)-N($U13)) | AM13: =IF($AL13="","",MAX(0,$AL13))
B14: =IF($C$3="","",$C$3+8) -> 46259 | C14: =IF($B14="","",IF($B14-$C$3+1>28,"Closeout","Week "&ROUNDUP(($B14-$C$3+1)/7,0))) -> Week 2 | T14: =IF($E$3="","",$E$3) -> 0.1 | Z14: =IF(N($I14)=0,"",IFERROR($J14/$I14,"")) | AA14: =IF(N($J14)=0,"",IFERROR($H14/$J14,"")) | AB14: =IF(N($J14)=0,"",IFERROR($K14/$J14,"")) | AC14: =IF(N($K14)=0,"",IFERROR($L14/$K14,"")) | AD14: =IF(N($L14)=0,"",IFERROR($M14/$L14,"")) | AE14: =IF(N($M14)=0,"",IFERROR($N14/$M14,"")) | AF14: =IF(N($N14)=0,"",IFERROR($P14/$N14,"")) | AG14: =IF(N($P14)=0,"",IFERROR($S14/$P14,"")) | AH14: =IF($S14="","",$S14*N($T14)) | AI14: =IF(N($P14)=0,"",IFERROR($H14/$P14,"")) | AJ14: =IF($AG14="","",$AG14*N($T14)) | AK14: =IF(N($H14)=0,"",IFERROR($S14/$H14,"")) | AL14: =IF(AND($H14="",$S14=""),"",N($AH14)-N($H14)-N($U14)) | AM14: =IF($AL14="","",MAX(0,$AL14))
B15: =IF($C$3="","",$C$3+9) -> 46260 | C15: =IF($B15="","",IF($B15-$C$3+1>28,"Closeout","Week "&ROUNDUP(($B15-$C$3+1)/7,0))) -> Week 2 | T15: =IF($E$3="","",$E$3) -> 0.1 | Z15: =IF(N($I15)=0,"",IFERROR($J15/$I15,"")) | AA15: =IF(N($J15)=0,"",IFERROR($H15/$J15,"")) | AB15: =IF(N($J15)=0,"",IFERROR($K15/$J15,"")) | AC15: =IF(N($K15)=0,"",IFERROR($L15/$K15,"")) | AD15: =IF(N($L15)=0,"",IFERROR($M15/$L15,"")) | AE15: =IF(N($M15)=0,"",IFERROR($N15/$M15,"")) | AF15: =IF(N($N15)=0,"",IFERROR($P15/$N15,"")) | AG15: =IF(N($P15)=0,"",IFERROR($S15/$P15,"")) | AH15: =IF($S15="","",$S15*N($T15)) | AI15: =IF(N($P15)=0,"",IFERROR($H15/$P15,"")) | AJ15: =IF($AG15="","",$AG15*N($T15)) | AK15: =IF(N($H15)=0,"",IFERROR($S15/$H15,"")) | AL15: =IF(AND($H15="",$S15=""),"",N($AH15)-N($H15)-N($U15)) | AM15: =IF($AL15="","",MAX(0,$AL15))
B16: =IF($C$3="","",$C$3+10) -> 46261 | C16: =IF($B16="","",IF($B16-$C$3+1>28,"Closeout","Week "&ROUNDUP(($B16-$C$3+1)/7,0))) -> Week 2 | T16: =IF($E$3="","",$E$3) -> 0.1 | Z16: =IF(N($I16)=0,"",IFERROR($J16/$I16,"")) | AA16: =IF(N($J16)=0,"",IFERROR($H16/$J16,"")) | AB16: =IF(N($J16)=0,"",IFERROR($K16/$J16,"")) | AC16: =IF(N($K16)=0,"",IFERROR($L16/$K16,"")) | AD16: =IF(N($L16)=0,"",IFERROR($M16/$L16,"")) | AE16: =IF(N($M16)=0,"",IFERROR($N16/$M16,"")) | AF16: =IF(N($N16)=0,"",IFERROR($P16/$N16,"")) | AG16: =IF(N($P16)=0,"",IFERROR($S16/$P16,"")) | AH16: =IF($S16="","",$S16*N($T16)) | AI16: =IF(N($P16)=0,"",IFERROR($H16/$P16,"")) | AJ16: =IF($AG16="","",$AG16*N($T16)) | AK16: =IF(N($H16)=0,"",IFERROR($S16/$H16,"")) | AL16: =IF(AND($H16="",$S16=""),"",N($AH16)-N($H16)-N($U16)) | AM16: =IF($AL16="","",MAX(0,$AL16))
B17: =IF($C$3="","",$C$3+11) -> 46262 | C17: =IF($B17="","",IF($B17-$C$3+1>28,"Closeout","Week "&ROUNDUP(($B17-$C$3+1)/7,0))) -> Week 2 | T17: =IF($E$3="","",$E$3) -> 0.1 | Z17: =IF(N($I17)=0,"",IFERROR($J17/$I17,"")) | AA17: =IF(N($J17)=0,"",IFERROR($H17/$J17,"")) | AB17: =IF(N($J17)=0,"",IFERROR($K17/$J17,"")) | AC17: =IF(N($K17)=0,"",IFERROR($L17/$K17,"")) | AD17: =IF(N($L17)=0,"",IFERROR($M17/$L17,"")) | AE17: =IF(N($M17)=0,"",IFERROR($N17/$M17,"")) | AF17: =IF(N($N17)=0,"",IFERROR($P17/$N17,"")) | AG17: =IF(N($P17)=0,"",IFERROR($S17/$P17,"")) | AH17: =IF($S17="","",$S17*N($T17)) | AI17: =IF(N($P17)=0,"",IFERROR($H17/$P17,"")) | AJ17: =IF($AG17="","",$AG17*N($T17)) | AK17: =IF(N($H17)=0,"",IFERROR($S17/$H17,"")) | AL17: =IF(AND($H17="",$S17=""),"",N($AH17)-N($H17)-N($U17)) | AM17: =IF($AL17="","",MAX(0,$AL17))
B18: =IF($C$3="","",$C$3+12) -> 46263 | C18: =IF($B18="","",IF($B18-$C$3+1>28,"Closeout","Week "&ROUNDUP(($B18-$C$3+1)/7,0))) -> Week 2 | T18: =IF($E$3="","",$E$3) -> 0.1 | Z18: =IF(N($I18)=0,"",IFERROR($J18/$I18,"")) | AA18: =IF(N($J18)=0,"",IFERROR($H18/$J18,"")) | AB18: =IF(N($J18)=0,"",IFERROR($K18/$J18,"")) | AC18: =IF(N($K18)=0,"",IFERROR($L18/$K18,"")) | AD18: =IF(N($L18)=0,"",IFERROR($M18/$L18,"")) | AE18: =IF(N($M18)=0,"",IFERROR($N18/$M18,"")) | AF18: =IF(N($N18)=0,"",IFERROR($P18/$N18,"")) | AG18: =IF(N($P18)=0,"",IFERROR($S18/$P18,"")) | AH18: =IF($S18="","",$S18*N($T18)) | AI18: =IF(N($P18)=0,"",IFERROR($H18/$P18,"")) | AJ18: =IF($AG18="","",$AG18*N($T18)) | AK18: =IF(N($H18)=0,"",IFERROR($S18/$H18,"")) | AL18: =IF(AND($H18="",$S18=""),"",N($AH18)-N($H18)-N($U18)) | AM18: =IF($AL18="","",MAX(0,$AL18))
B19: =IF($C$3="","",$C$3+13) -> 46264 | C19: =IF($B19="","",IF($B19-$C$3+1>28,"Closeout","Week "&ROUNDUP(($B19-$C$3+1)/7,0))) -> Week 2 | T19: =IF($E$3="","",$E$3) -> 0.1 | Z19: =IF(N($I19)=0,"",IFERROR($J19/$I19,"")) | AA19: =IF(N($J19)=0,"",IFERROR($H19/$J19,"")) | AB19: =IF(N($J19)=0,"",IFERROR($K19/$J19,"")) | AC19: =IF(N($K19)=0,"",IFERROR($L19/$K19,"")) | AD19: =IF(N($L19)=0,"",IFERROR($M19/$L19,"")) | AE19: =IF(N($M19)=0,"",IFERROR($N19/$M19,"")) | AF19: =IF(N($N19)=0,"",IFERROR($P19/$N19,"")) | AG19: =IF(N($P19)=0,"",IFERROR($S19/$P19,"")) | AH19: =IF($S19="","",$S19*N($T19)) | AI19: =IF(N($P19)=0,"",IFERROR($H19/$P19,"")) | AJ19: =IF($AG19="","",$AG19*N($T19)) | AK19: =IF(N($H19)=0,"",IFERROR($S19/$H19,"")) | AL19: =IF(AND($H19="",$S19=""),"",N($AH19)-N($H19)-N($U19)) | AM19: =IF($AL19="","",MAX(0,$AL19))
B20: =IF($C$3="","",$C$3+14) -> 46265 | C20: =IF($B20="","",IF($B20-$C$3+1>28,"Closeout","Week "&ROUNDUP(($B20-$C$3+1)/7,0))) -> Week 3 | T20: =IF($E$3="","",$E$3) -> 0.1 | Z20: =IF(N($I20)=0,"",IFERROR($J20/$I20,"")) | AA20: =IF(N($J20)=0,"",IFERROR($H20/$J20,"")) | AB20: =IF(N($J20)=0,"",IFERROR($K20/$J20,"")) | AC20: =IF(N($K20)=0,"",IFERROR($L20/$K20,"")) | AD20: =IF(N($L20)=0,"",IFERROR($M20/$L20,"")) | AE20: =IF(N($M20)=0,"",IFERROR($N20/$M20,"")) | AF20: =IF(N($N20)=0,"",IFERROR($P20/$N20,"")) | AG20: =IF(N($P20)=0,"",IFERROR($S20/$P20,"")) | AH20: =IF($S20="","",$S20*N($T20)) | AI20: =IF(N($P20)=0,"",IFERROR($H20/$P20,"")) | AJ20: =IF($AG20="","",$AG20*N($T20)) | AK20: =IF(N($H20)=0,"",IFERROR($S20/$H20,"")) | AL20: =IF(AND($H20="",$S20=""),"",N($AH20)-N($H20)-N($U20)) | AM20: =IF($AL20="","",MAX(0,$AL20))
B21: =IF($C$3="","",$C$3+15) -> 46266 | C21: =IF($B21="","",IF($B21-$C$3+1>28,"Closeout","Week "&ROUNDUP(($B21-$C$3+1)/7,0))) -> Week 3 | T21: =IF($E$3="","",$E$3) -> 0.1 | Z21: =IF(N($I21)=0,"",IFERROR($J21/$I21,"")) | AA21: =IF(N($J21)=0,"",IFERROR($H21/$J21,"")) | AB21: =IF(N($J21)=0,"",IFERROR($K21/$J21,"")) | AC21: =IF(N($K21)=0,"",IFERROR($L21/$K21,"")) | AD21: =IF(N($L21)=0,"",IFERROR($M21/$L21,"")) | AE21: =IF(N($M21)=0,"",IFERROR($N21/$M21,"")) | AF21: =IF(N($N21)=0,"",IFERROR($P21/$N21,"")) | AG21: =IF(N($P21)=0,"",IFERROR($S21/$P21,"")) | AH21: =IF($S21="","",$S21*N($T21)) | AI21: =IF(N($P21)=0,"",IFERROR($H21/$P21,"")) | AJ21: =IF($AG21="","",$AG21*N($T21)) | AK21: =IF(N($H21)=0,"",IFERROR($S21/$H21,"")) | AL21: =IF(AND($H21="",$S21=""),"",N($AH21)-N($H21)-N($U21)) | AM21: =IF($AL21="","",MAX(0,$AL21))
B22: =IF($C$3="","",$C$3+16) -> 46267 | C22: =IF($B22="","",IF($B22-$C$3+1>28,"Closeout","Week "&ROUNDUP(($B22-$C$3+1)/7,0))) -> Week 3 | T22: =IF($E$3="","",$E$3) -> 0.1 | Z22: =IF(N($I22)=0,"",IFERROR($J22/$I22,"")) | AA22: =IF(N($J22)=0,"",IFERROR($H22/$J22,"")) | AB22: =IF(N($J22)=0,"",IFERROR($K22/$J22,"")) | AC22: =IF(N($K22)=0,"",IFERROR($L22/$K22,"")) | AD22: =IF(N($L22)=0,"",IFERROR($M22/$L22,"")) | AE22: =IF(N($M22)=0,"",IFERROR($N22/$M22,"")) | AF22: =IF(N($N22)=0,"",IFERROR($P22/$N22,"")) | AG22: =IF(N($P22)=0,"",IFERROR($S22/$P22,"")) | AH22: =IF($S22="","",$S22*N($T22)) | AI22: =IF(N($P22)=0,"",IFERROR($H22/$P22,"")) | AJ22: =IF($AG22="","",$AG22*N($T22)) | AK22: =IF(N($H22)=0,"",IFERROR($S22/$H22,"")) | AL22: =IF(AND($H22="",$S22=""),"",N($AH22)-N($H22)-N($U22)) | AM22: =IF($AL22="","",MAX(0,$AL22))
B23: =IF($C$3="","",$C$3+17) -> 46268 | C23: =IF($B23="","",IF($B23-$C$3+1>28,"Closeout","Week "&ROUNDUP(($B23-$C$3+1)/7,0))) -> Week 3 | T23: =IF($E$3="","",$E$3) -> 0.1 | Z23: =IF(N($I23)=0,"",IFERROR($J23/$I23,"")) | AA23: =IF(N($J23)=0,"",IFERROR($H23/$J23,"")) | AB23: =IF(N($J23)=0,"",IFERROR($K23/$J23,"")) | AC23: =IF(N($K23)=0,"",IFERROR($L23/$K23,"")) | AD23: =IF(N($L23)=0,"",IFERROR($M23/$L23,"")) | AE23: =IF(N($M23)=0,"",IFERROR($N23/$M23,"")) | AF23: =IF(N($N23)=0,"",IFERROR($P23/$N23,"")) | AG23: =IF(N($P23)=0,"",IFERROR($S23/$P23,"")) | AH23: =IF($S23="","",$S23*N($T23)) | AI23: =IF(N($P23)=0,"",IFERROR($H23/$P23,"")) | AJ23: =IF($AG23="","",$AG23*N($T23)) | AK23: =IF(N($H23)=0,"",IFERROR($S23/$H23,"")) | AL23: =IF(AND($H23="",$S23=""),"",N($AH23)-N($H23)-N($U23)) | AM23: =IF($AL23="","",MAX(0,$AL23))
B24: =IF($C$3="","",$C$3+18) -> 46269 | C24: =IF($B24="","",IF($B24-$C$3+1>28,"Closeout","Week "&ROUNDUP(($B24-$C$3+1)/7,0))) -> Week 3 | T24: =IF($E$3="","",$E$3) -> 0.1 | Z24: =IF(N($I24)=0,"",IFERROR($J24/$I24,"")) | AA24: =IF(N($J24)=0,"",IFERROR($H24/$J24,"")) | AB24: =IF(N($J24)=0,"",IFERROR($K24/$J24,"")) | AC24: =IF(N($K24)=0,"",IFERROR($L24/$K24,"")) | AD24: =IF(N($L24)=0,"",IFERROR($M24/$L24,"")) | AE24: =IF(N($M24)=0,"",IFERROR($N24/$M24,"")) | AF24: =IF(N($N24)=0,"",IFERROR($P24/$N24,"")) | AG24: =IF(N($P24)=0,"",IFERROR($S24/$P24,"")) | AH24: =IF($S24="","",$S24*N($T24)) | AI24: =IF(N($P24)=0,"",IFERROR($H24/$P24,"")) | AJ24: =IF($AG24="","",$AG24*N($T24)) | AK24: =IF(N($H24)=0,"",IFERROR($S24/$H24,"")) | AL24: =IF(AND($H24="",$S24=""),"",N($AH24)-N($H24)-N($U24)) | AM24: =IF($AL24="","",MAX(0,$AL24))
B25: =IF($C$3="","",$C$3+19) -> 46270 | C25: =IF($B25="","",IF($B25-$C$3+1>28,"Closeout","Week "&ROUNDUP(($B25-$C$3+1)/7,0))) -> Week 3 | T25: =IF($E$3="","",$E$3) -> 0.1 | Z25: =IF(N($I25)=0,"",IFERROR($J25/$I25,"")) | AA25: =IF(N($J25)=0,"",IFERROR($H25/$J25,"")) | AB25: =IF(N($J25)=0,"",IFERROR($K25/$J25,"")) | AC25: =IF(N($K25)=0,"",IFERROR($L25/$K25,"")) | AD25: =IF(N($L25)=0,"",IFERROR($M25/$L25,"")) | AE25: =IF(N($M25)=0,"",IFERROR($N25/$M25,"")) | AF25: =IF(N($N25)=0,"",IFERROR($P25/$N25,"")) | AG25: =IF(N($P25)=0,"",IFERROR($S25/$P25,"")) | AH25: =IF($S25="","",$S25*N($T25)) | AI25: =IF(N($P25)=0,"",IFERROR($H25/$P25,"")) | AJ25: =IF($AG25="","",$AG25*N($T25)) | AK25: =IF(N($H25)=0,"",IFERROR($S25/$H25,"")) | AL25: =IF(AND($H25="",$S25=""),"",N($AH25)-N($H25)-N($U25)) | AM25: =IF($AL25="","",MAX(0,$AL25))
B26: =IF($C$3="","",$C$3+20) -> 46271 | C26: =IF($B26="","",IF($B26-$C$3+1>28,"Closeout","Week "&ROUNDUP(($B26-$C$3+1)/7,0))) -> Week 3 | T26: =IF($E$3="","",$E$3) -> 0.1 | Z26: =IF(N($I26)=0,"",IFERROR($J26/$I26,"")) | AA26: =IF(N($J26)=0,"",IFERROR($H26/$J26,"")) | AB26: =IF(N($J26)=0,"",IFERROR($K26/$J26,"")) | AC26: =IF(N($K26)=0,"",IFERROR($L26/$K26,"")) | AD26: =IF(N($L26)=0,"",IFERROR($M26/$L26,"")) | AE26: =IF(N($M26)=0,"",IFERROR($N26/$M26,"")) | AF26: =IF(N($N26)=0,"",IFERROR($P26/$N26,"")) | AG26: =IF(N($P26)=0,"",IFERROR($S26/$P26,"")) | AH26: =IF($S26="","",$S26*N($T26)) | AI26: =IF(N($P26)=0,"",IFERROR($H26/$P26,"")) | AJ26: =IF($AG26="","",$AG26*N($T26)) | AK26: =IF(N($H26)=0,"",IFERROR($S26/$H26,"")) | AL26: =IF(AND($H26="",$S26=""),"",N($AH26)-N($H26)-N($U26)) | AM26: =IF($AL26="","",MAX(0,$AL26))
B27: =IF($C$3="","",$C$3+21) -> 46272 | C27: =IF($B27="","",IF($B27-$C$3+1>28,"Closeout","Week "&ROUNDUP(($B27-$C$3+1)/7,0))) -> Week 4 | T27: =IF($E$3="","",$E$3) -> 0.1 | Z27: =IF(N($I27)=0,"",IFERROR($J27/$I27,"")) | AA27: =IF(N($J27)=0,"",IFERROR($H27/$J27,"")) | AB27: =IF(N($J27)=0,"",IFERROR($K27/$J27,"")) | AC27: =IF(N($K27)=0,"",IFERROR($L27/$K27,"")) | AD27: =IF(N($L27)=0,"",IFERROR($M27/$L27,"")) | AE27: =IF(N($M27)=0,"",IFERROR($N27/$M27,"")) | AF27: =IF(N($N27)=0,"",IFERROR($P27/$N27,"")) | AG27: =IF(N($P27)=0,"",IFERROR($S27/$P27,"")) | AH27: =IF($S27="","",$S27*N($T27)) | AI27: =IF(N($P27)=0,"",IFERROR($H27/$P27,"")) | AJ27: =IF($AG27="","",$AG27*N($T27)) | AK27: =IF(N($H27)=0,"",IFERROR($S27/$H27,"")) | AL27: =IF(AND($H27="",$S27=""),"",N($AH27)-N($H27)-N($U27)) | AM27: =IF($AL27="","",MAX(0,$AL27))
B28: =IF($C$3="","",$C$3+22) -> 46273 | C28: =IF($B28="","",IF($B28-$C$3+1>28,"Closeout","Week "&ROUNDUP(($B28-$C$3+1)/7,0))) -> Week 4 | T28: =IF($E$3="","",$E$3) -> 0.1 | Z28: =IF(N($I28)=0,"",IFERROR($J28/$I28,"")) | AA28: =IF(N($J28)=0,"",IFERROR($H28/$J28,"")) | AB28: =IF(N($J28)=0,"",IFERROR($K28/$J28,"")) | AC28: =IF(N($K28)=0,"",IFERROR($L28/$K28,"")) | AD28: =IF(N($L28)=0,"",IFERROR($M28/$L28,"")) | AE28: =IF(N($M28)=0,"",IFERROR($N28/$M28,"")) | AF28: =IF(N($N28)=0,"",IFERROR($P28/$N28,"")) | AG28: =IF(N($P28)=0,"",IFERROR($S28/$P28,"")) | AH28: =IF($S28="","",$S28*N($T28)) | AI28: =IF(N($P28)=0,"",IFERROR($H28/$P28,"")) | AJ28: =IF($AG28="","",$AG28*N($T28)) | AK28: =IF(N($H28)=0,"",IFERROR($S28/$H28,"")) | AL28: =IF(AND($H28="",$S28=""),"",N($AH28)-N($H28)-N($U28)) | AM28: =IF($AL28="","",MAX(0,$AL28))
B29: =IF($C$3="","",$C$3+23) -> 46274 | C29: =IF($B29="","",IF($B29-$C$3+1>28,"Closeout","Week "&ROUNDUP(($B29-$C$3+1)/7,0))) -> Week 4 | T29: =IF($E$3="","",$E$3) -> 0.1 | Z29: =IF(N($I29)=0,"",IFERROR($J29/$I29,"")) | AA29: =IF(N($J29)=0,"",IFERROR($H29/$J29,"")) | AB29: =IF(N($J29)=0,"",IFERROR($K29/$J29,"")) | AC29: =IF(N($K29)=0,"",IFERROR($L29/$K29,"")) | AD29: =IF(N($L29)=0,"",IFERROR($M29/$L29,"")) | AE29: =IF(N($M29)=0,"",IFERROR($N29/$M29,"")) | AF29: =IF(N($N29)=0,"",IFERROR($P29/$N29,"")) | AG29: =IF(N($P29)=0,"",IFERROR($S29/$P29,"")) | AH29: =IF($S29="","",$S29*N($T29)) | AI29: =IF(N($P29)=0,"",IFERROR($H29/$P29,"")) | AJ29: =IF($AG29="","",$AG29*N($T29)) | AK29: =IF(N($H29)=0,"",IFERROR($S29/$H29,"")) | AL29: =IF(AND($H29="",$S29=""),"",N($AH29)-N($H29)-N($U29)) | AM29: =IF($AL29="","",MAX(0,$AL29))
B30: =IF($C$3="","",$C$3+24) -> 46275 | C30: =IF($B30="","",IF($B30-$C$3+1>28,"Closeout","Week "&ROUNDUP(($B30-$C$3+1)/7,0))) -> Week 4 | T30: =IF($E$3="","",$E$3) -> 0.1 | Z30: =IF(N($I30)=0,"",IFERROR($J30/$I30,"")) | AA30: =IF(N($J30)=0,"",IFERROR($H30/$J30,"")) | AB30: =IF(N($J30)=0,"",IFERROR($K30/$J30,"")) | AC30: =IF(N($K30)=0,"",IFERROR($L30/$K30,"")) | AD30: =IF(N($L30)=0,"",IFERROR($M30/$L30,"")) | AE30: =IF(N($M30)=0,"",IFERROR($N30/$M30,"")) | AF30: =IF(N($N30)=0,"",IFERROR($P30/$N30,"")) | AG30: =IF(N($P30)=0,"",IFERROR($S30/$P30,"")) | AH30: =IF($S30="","",$S30*N($T30)) | AI30: =IF(N($P30)=0,"",IFERROR($H30/$P30,"")) | AJ30: =IF($AG30="","",$AG30*N($T30)) | AK30: =IF(N($H30)=0,"",IFERROR($S30/$H30,"")) | AL30: =IF(AND($H30="",$S30=""),"",N($AH30)-N($H30)-N($U30)) | AM30: =IF($AL30="","",MAX(0,$AL30))
B31: =IF($C$3="","",$C$3+25) -> 46276 | C31: =IF($B31="","",IF($B31-$C$3+1>28,"Closeout","Week "&ROUNDUP(($B31-$C$3+1)/7,0))) -> Week 4 | T31: =IF($E$3="","",$E$3) -> 0.1 | Z31: =IF(N($I31)=0,"",IFERROR($J31/$I31,"")) | AA31: =IF(N($J31)=0,"",IFERROR($H31/$J31,"")) | AB31: =IF(N($J31)=0,"",IFERROR($K31/$J31,"")) | AC31: =IF(N($K31)=0,"",IFERROR($L31/$K31,"")) | AD31: =IF(N($L31)=0,"",IFERROR($M31/$L31,"")) | AE31: =IF(N($M31)=0,"",IFERROR($N31/$M31,"")) | AF31: =IF(N($N31)=0,"",IFERROR($P31/$N31,"")) | AG31: =IF(N($P31)=0,"",IFERROR($S31/$P31,"")) | AH31: =IF($S31="","",$S31*N($T31)) | AI31: =IF(N($P31)=0,"",IFERROR($H31/$P31,"")) | AJ31: =IF($AG31="","",$AG31*N($T31)) | AK31: =IF(N($H31)=0,"",IFERROR($S31/$H31,"")) | AL31: =IF(AND($H31="",$S31=""),"",N($AH31)-N($H31)-N($U31)) | AM31: =IF($AL31="","",MAX(0,$AL31))
B32: =IF($C$3="","",$C$3+26) -> 46277 | C32: =IF($B32="","",IF($B32-$C$3+1>28,"Closeout","Week "&ROUNDUP(($B32-$C$3+1)/7,0))) -> Week 4 | T32: =IF($E$3="","",$E$3) -> 0.1 | Z32: =IF(N($I32)=0,"",IFERROR($J32/$I32,"")) | AA32: =IF(N($J32)=0,"",IFERROR($H32/$J32,"")) | AB32: =IF(N($J32)=0,"",IFERROR($K32/$J32,"")) | AC32: =IF(N($K32)=0,"",IFERROR($L32/$K32,"")) | AD32: =IF(N($L32)=0,"",IFERROR($M32/$L32,"")) | AE32: =IF(N($M32)=0,"",IFERROR($N32/$M32,"")) | AF32: =IF(N($N32)=0,"",IFERROR($P32/$N32,"")) | AG32: =IF(N($P32)=0,"",IFERROR($S32/$P32,"")) | AH32: =IF($S32="","",$S32*N($T32)) | AI32: =IF(N($P32)=0,"",IFERROR($H32/$P32,"")) | AJ32: =IF($AG32="","",$AG32*N($T32)) | AK32: =IF(N($H32)=0,"",IFERROR($S32/$H32,"")) | AL32: =IF(AND($H32="",$S32=""),"",N($AH32)-N($H32)-N($U32)) | AM32: =IF($AL32="","",MAX(0,$AL32))
B33: =IF($C$3="","",$C$3+27) -> 46278 | C33: =IF($B33="","",IF($B33-$C$3+1>28,"Closeout","Week "&ROUNDUP(($B33-$C$3+1)/7,0))) -> Week 4 | T33: =IF($E$3="","",$E$3) -> 0.1 | Z33: =IF(N($I33)=0,"",IFERROR($J33/$I33,"")) | AA33: =IF(N($J33)=0,"",IFERROR($H33/$J33,"")) | AB33: =IF(N($J33)=0,"",IFERROR($K33/$J33,"")) | AC33: =IF(N($K33)=0,"",IFERROR($L33/$K33,"")) | AD33: =IF(N($L33)=0,"",IFERROR($M33/$L33,"")) | AE33: =IF(N($M33)=0,"",IFERROR($N33/$M33,"")) | AF33: =IF(N($N33)=0,"",IFERROR($P33/$N33,"")) | AG33: =IF(N($P33)=0,"",IFERROR($S33/$P33,"")) | AH33: =IF($S33="","",$S33*N($T33)) | AI33: =IF(N($P33)=0,"",IFERROR($H33/$P33,"")) | AJ33: =IF($AG33="","",$AG33*N($T33)) | AK33: =IF(N($H33)=0,"",IFERROR($S33/$H33,"")) | AL33: =IF(AND($H33="",$S33=""),"",N($AH33)-N($H33)-N($U33)) | AM33: =IF($AL33="","",MAX(0,$AL33))
B34: =IF($C$3="","",$C$3+28) -> 46279 | C34: =IF($B34="","",IF($B34-$C$3+1>28,"Closeout","Week "&ROUNDUP(($B34-$C$3+1)/7,0))) -> Closeout | T34: =IF($E$3="","",$E$3) -> 0.1 | Z34: =IF(N($I34)=0,"",IFERROR($J34/$I34,"")) | AA34: =IF(N($J34)=0,"",IFERROR($H34/$J34,"")) | AB34: =IF(N($J34)=0,"",IFERROR($K34/$J34,"")) | AC34: =IF(N($K34)=0,"",IFERROR($L34/$K34,"")) | AD34: =IF(N($L34)=0,"",IFERROR($M34/$L34,"")) | AE34: =IF(N($M34)=0,"",IFERROR($N34/$M34,"")) | AF34: =IF(N($N34)=0,"",IFERROR($P34/$N34,"")) | AG34: =IF(N($P34)=0,"",IFERROR($S34/$P34,"")) | AH34: =IF($S34="","",$S34*N($T34)) | AI34: =IF(N($P34)=0,"",IFERROR($H34/$P34,"")) | AJ34: =IF($AG34="","",$AG34*N($T34)) | AK34: =IF(N($H34)=0,"",IFERROR($S34/$H34,"")) | AL34: =IF(AND($H34="",$S34=""),"",N($AH34)-N($H34)-N($U34)) | AM34: =IF($AL34="","",MAX(0,$AL34))
B35: =IF($C$3="","",$C$3+29) -> 46280 | C35: =IF($B35="","",IF($B35-$C$3+1>28,"Closeout","Week "&ROUNDUP(($B35-$C$3+1)/7,0))) -> Closeout | T35: =IF($E$3="","",$E$3) -> 0.1 | Z35: =IF(N($I35)=0,"",IFERROR($J35/$I35,"")) | AA35: =IF(N($J35)=0,"",IFERROR($H35/$J35,"")) | AB35: =IF(N($J35)=0,"",IFERROR($K35/$J35,"")) | AC35: =IF(N($K35)=0,"",IFERROR($L35/$K35,"")) | AD35: =IF(N($L35)=0,"",IFERROR($M35/$L35,"")) | AE35: =IF(N($M35)=0,"",IFERROR($N35/$M35,"")) | AF35: =IF(N($N35)=0,"",IFERROR($P35/$N35,"")) | AG35: =IF(N($P35)=0,"",IFERROR($S35/$P35,"")) | AH35: =IF($S35="","",$S35*N($T35)) | AI35: =IF(N($P35)=0,"",IFERROR($H35/$P35,"")) | AJ35: =IF($AG35="","",$AG35*N($T35)) | AK35: =IF(N($H35)=0,"",IFERROR($S35/$H35,"")) | AL35: =IF(AND($H35="",$S35=""),"",N($AH35)-N($H35)-N($U35)) | AM35: =IF($AL35="","",MAX(0,$AL35))
B37: MONTH TOTAL (raw aggregation of all 30 days) | H37: =SUM(H6:H35) -> 0 | I37: =SUM(I6:I35) -> 0 | J37: =SUM(J6:J35) -> 0 | K37: =SUM(K6:K35) -> 0 | L37: =SUM(L6:L35) -> 0 | M37: =SUM(M6:M35) -> 0 | N37: =SUM(N6:N35) -> 0 | O37: =SUM(O6:O35) -> 0 | ... S37: =SUM(S6:S35) -> 0 | T37: =IFERROR(IF(N(S37)=0,"",AH37/S37),"") | U37: =SUM(U6:U35) -> 0 | Z37: =IF(N(I37)=0,"",J37/I37) | AA37: =IF(N(J37)=0,"",H37/J37) | AB37: =IF(N(J37)=0,"",K37/J37) | AC37: =IF(N(K37)=0,"",L37/K37) | AD37: =IF(N(L37)=0,"",M37/L37) | AE37: =IF(N(M37)=0,"",N37/M37) | AF37: =IF(N(N37)=0,"",P37/N37) | AG37: =IF(N(P37)=0,"",S37/P37) | AH37: =SUM(AH6:AH35) -> 0 | AI37: =IF(N(P37)=0,"",H37/P37) | AJ37: =IF(AG37="","",AG37*N(T37)) | AK37: =IF(N(H37)=0,"",S37/H37) | AL37: =SUM(AL6:AL35) -> 0 | AM37: =SUM(AM6:AM35) -> 0

Sheet Weekly Summary
B2: Weekly Summary — Bridge Aggregation | E2: Stated contribution margin | H2: ='Daily Input'!$E$3 -> 0.1
B3: 30-day spend ceiling (R$) | C3: ='Daily Input'!$I$3 -> 600 | D3: Break-even ROAS (x) | E3: =IF(N('Daily Input'!$E$3)=0,"",1/'Daily Input'!$E$3) -> 10 | F3: Path-stop floor (R$) | G3: 40
B4: Every figure is a SUMIFS/SUM aggregation of raw Daily Input rows. Rates are computed from summed numerators and denominators — never as an average of daily averages. Blank means no data, not zero.
B5: Metric | C5: Week 1 · Days 1–7 | D5: Week 2 · Days 8–14 | E5: Week 3 · Days 15–21 | F5: Week 4 · Days 22–28 | G5: Closeout · Days 29–30 | H5: Month Total
B6: SUMIFS key → | C6: Week 1 | D6: Week 2 | E6: Week 3 | F6: Week 4 | G6: Closeout | H6: All 30 days
B7: CORE ECONOMICS
B8: Spend (R$) | C8: =SUMIFS('Daily Input'!$H$6:$H$35,'Daily Input'!$C$6:$C$35,C$6) -> 0 | D8: =SUMIFS('Daily Input'!$H$6:$H$35,'Daily Input'!$C$6:$C$35,D$6) -> 0 | E8: =SUMIFS('Daily Input'!$H$6:$H$35,'Daily Input'!$C$6:$C$35,E$6) -> 0 | F8: =SUMIFS('Daily Input'!$H$6:$H$35,'Daily Input'!$C$6:$C$35,F$6) -> 0 | G8: =SUMIFS('Daily Input'!$H$6:$H$35,'Daily Input'!$C$6:$C$35,G$6) -> 0 | H8: =SUM('Daily Input'!$H$6:$H$35) -> 0
B9: Gross Attributed Revenue (R$) | C9: =SUMIFS('Daily Input'!$Q$6:$Q$35,'Daily Input'!$C$6:$C$35,C$6) -> 0 | D9: =SUMIFS('Daily Input'!$Q$6:$Q$35,'Daily Input'!$C$6:$C$35,D$6) -> 0 | E9: =SUMIFS('Daily Input'!$Q$6:$Q$35,'Daily Input'!$C$6:$C$35,E$6) -> 0 | F9: =SUMIFS('Daily Input'!$Q$6:$Q$35,'Daily Input'!$C$6:$C$35,F$6) -> 0 | G9: =SUMIFS('Daily Input'!$Q$6:$Q$35,'Daily Input'!$C$6:$C$35,G$6) -> 0 | H9: =SUM('Daily Input'!$Q$6:$Q$35) -> 0
B10: Cancellations / Refunds (R$) | C10: =SUMIFS('Daily Input'!$R$6:$R$35,'Daily Input'!$C$6:$C$35,C$6) -> 0 | D10: =SUMIFS('Daily Input'!$R$6:$R$35,'Daily Input'!$C$6:$C$35,D$6) -> 0 | E10: =SUMIFS('Daily Input'!$R$6:$R$35,'Daily Input'!$C$6:$C$35,E$6) -> 0 | F10: =SUMIFS('Daily Input'!$R$6:$R$35,'Daily Input'!$C$6:$C$35,F$6) -> 0 | G10: =SUMIFS('Daily Input'!$R$6:$R$35,'Daily Input'!$C$6:$C$35,G$6) -> 0 | H10: =SUM('Daily Input'!$R$6:$R$35) -> 0
B11: Settled Attributed Revenue (R$) | C11: =SUMIFS('Daily Input'!$S$6:$S$35,'Daily Input'!$C$6:$C$35,C$6) -> 0 | D11: =SUMIFS('Daily Input'!$S$6:$S$35,'Daily Input'!$C$6:$C$35,D$6) -> 0 | E11: =SUMIFS('Daily Input'!$S$6:$S$35,'Daily Input'!$C$6:$C$35,E$6) -> 0 | F11: =SUMIFS('Daily Input'!$S$6:$S$35,'Daily Input'!$C$6:$C$35,F$6) -> 0 | G11: =SUMIFS('Daily Input'!$S$6:$S$35,'Daily Input'!$C$6:$C$35,G$6) -> 0 | H11: =SUM('Daily Input'!$S$6:$S$35) -> 0
B12: Attributed Orders | C12: =SUMIFS('Daily Input'!$O$6:$O$35,'Daily Input'!$C$6:$C$35,C$6) -> 0 | D12: =SUMIFS('Daily Input'!$O$6:$O$35,'Daily Input'!$C$6:$C$35,D$6) -> 0 | E12: =SUMIFS('Daily Input'!$O$6:$O$35,'Daily Input'!$C$6:$C$35,E$6) -> 0 | F12: =SUMIFS('Daily Input'!$O$6:$O$35,'Daily Input'!$C$6:$C$35,F$6) -> 0 | G12: =SUMIFS('Daily Input'!$O$6:$O$35,'Daily Input'!$C$6:$C$35,G$6) -> 0 | H12: =SUM('Daily Input'!$O$6:$O$35) -> 0
B13: Fulfilled Attributed Orders | C13: =SUMIFS('Daily Input'!$P$6:$P$35,'Daily Input'!$C$6:$C$35,C$6) -> 0 | D13: =SUMIFS('Daily Input'!$P$6:$P$35,'Daily Input'!$C$6:$C$35,D$6) -> 0 | E13: =SUMIFS('Daily Input'!$P$6:$P$35,'Daily Input'!$C$6:$C$35,E$6) -> 0 | F13: =SUMIFS('Daily Input'!$P$6:$P$35,'Daily Input'!$C$6:$C$35,F$6) -> 0 | G13: =SUMIFS('Daily Input'!$P$6:$P$35,'Daily Input'!$C$6:$C$35,G$6) -> 0 | H13: =SUM('Daily Input'!$P$6:$P$35) -> 0
B14: AOV (R$) | C14: =IF(N(C13)=0,"",C11/C13) | D14: =IF(N(D13)=0,"",D11/D13) | E14: =IF(N(E13)=0,"",E11/E13) | F14: =IF(N(F13)=0,"",F11/F13) | G14: =IF(N(G13)=0,"",G11/G13) | H14: =IF(N(H13)=0,"",H11/H13)
B15: Verified Contribution Margin (%) | C15: =IF(N(C11)=0,"",C16/C11) | D15: =IF(N(D11)=0,"",D16/D11) | E15: =IF(N(E11)=0,"",E16/E11) | F15: =IF(N(F11)=0,"",F16/F11) | G15: =IF(N(G11)=0,"",G16/G11) | H15: =IF(N(H11)=0,"",H16/H11)
B16: Contribution (R$) | C16: =SUMIFS('Daily Input'!$AH$6:$AH$35,'Daily Input'!$C$6:$C$35,C$6) -> 0 | D16: =SUMIFS('Daily Input'!$AH$6:$AH$35,'Daily Input'!$C$6:$C$35,D$6) -> 0 | E16: =SUMIFS('Daily Input'!$AH$6:$AH$35,'Daily Input'!$C$6:$C$35,E$6) -> 0 | F16: =SUMIFS('Daily Input'!$AH$6:$AH$35,'Daily Input'!$C$6:$C$35,F$6) -> 0 | G16: =SUMIFS('Daily Input'!$AH$6:$AH$35,'Daily Input'!$C$6:$C$35,G$6) -> 0 | H16: =SUM('Daily Input'!$AH$6:$AH$35) -> 0
B17: Excluded Variable Costs (R$) | C17: =SUMIFS('Daily Input'!$U$6:$U$35,'Daily Input'!$C$6:$C$35,C$6) -> 0 | D17: =SUMIFS('Daily Input'!$U$6:$U$35,'Daily Input'!$C$6:$C$35,D$6) -> 0 | E17: =SUMIFS('Daily Input'!$U$6:$U$35,'Daily Input'!$C$6:$C$35,E$6) -> 0 | F17: =SUMIFS('Daily Input'!$U$6:$U$35,'Daily Input'!$C$6:$C$35,F$6) -> 0 | G17: =SUMIFS('Daily Input'!$U$6:$U$35,'Daily Input'!$C$6:$C$35,G$6) -> 0 | H17: =SUM('Daily Input'!$U$6:$U$35) -> 0
B18: CPA (R$) | C18: =IF(N(C13)=0,"",C8/C13) | D18: =IF(N(D13)=0,"",D8/D13) | E18: =IF(N(E13)=0,"",E8/E13) | F18: =IF(N(F13)=0,"",F8/F13) | G18: =IF(N(G13)=0,"",G8/G13) | H18: =IF(N(H13)=0,"",H8/H13)
B19: Maximum Allowable CAC (R$) | C19: =IF(C14="","",C14*N(C15)) | D19: =IF(D14="","",D14*N(D15)) | E19: =IF(E14="","",E14*N(E15)) | F19: =IF(F14="","",F14*N(F15)) | G19: =IF(G14="","",G14*N(G15)) | H19: =IF(H14="","",H14*N(H15))
B20: Blended ROAS (x) | C20: =IF(N(C8)=0,"",C11/C8) | D20: =IF(N(D8)=0,"",D11/D8) | E20: =IF(N(E8)=0,"",E11/E8) | F20: =IF(N(F8)=0,"",F11/F8) | G20: =IF(N(G8)=0,"",G11/G8) | H20: =IF(N(H8)=0,"",H11/H8)
B21: Marketing Profit (R$) | C21: =IF(N(C8)+N(C11)=0,"",C16-C8-C17) | D21: =IF(N(D8)+N(D11)=0,"",D16-D8-D17) | E21: =IF(N(E8)+N(E11)=0,"",E16-E8-E17) | F21: =IF(N(F8)+N(F11)=0,"",F16-F8-F17) | G21: =IF(N(G8)+N(G11)=0,"",G16-G8-G17) | H21: =IF(N(H8)+N(H11)=0,"",H16-H8-H17)
B22: Reinvestment Wallet (R$) | C22: =IF(C21="","",MAX(0,C21)) | D22: =IF(D21="","",MAX(0,D21)) | E22: =IF(E21="","",MAX(0,E21)) | F22: =IF(F21="","",MAX(0,F21)) | G22: =IF(G21="","",MAX(0,G21)) | H22: =IF(H21="","",MAX(0,H21))
B23: Break-even ROAS at verified margin (x) | C23: =IF(N(C15)=0,$E$3,1/C15) -> 10 | D23: =IF(N(D15)=0,$E$3,1/D15) -> 10 | E23: =IF(N(E15)=0,$E$3,1/E15) -> 10 | F23: =IF(N(F15)=0,$E$3,1/F15) -> 10 | G23: =IF(N(G15)=0,$E$3,1/G15) -> 10 | H23: =IF(N(H15)=0,$E$3,1/H15) -> 10
B25: FUNNEL DIAGNOSTICS (aggregated from raw rows)
B26: Impressions | C26: =SUMIFS('Daily Input'!$I$6:$I$35,'Daily Input'!$C$6:$C$35,C$6) -> 0 | D26: =SUMIFS('Daily Input'!$I$6:$I$35,'Daily Input'!$C$6:$C$35,D$6) -> 0 | E26: =SUMIFS('Daily Input'!$I$6:$I$35,'Daily Input'!$C$6:$C$35,E$6) -> 0 | F26: =SUMIFS('Daily Input'!$I$6:$I$35,'Daily Input'!$C$6:$C$35,F$6) -> 0 | G26: =SUMIFS('Daily Input'!$I$6:$I$35,'Daily Input'!$C$6:$C$35,G$6) -> 0 | H26: =SUM('Daily Input'!$I$6:$I$35) -> 0
B27: Link Clicks | C27: =SUMIFS('Daily Input'!$J$6:$J$35,'Daily Input'!$C$6:$C$35,C$6) -> 0 | D27: =SUMIFS('Daily Input'!$J$6:$J$35,'Daily Input'!$C$6:$C$35,D$6) -> 0 | E27: =SUMIFS('Daily Input'!$J$6:$J$35,'Daily Input'!$C$6:$C$35,E$6) -> 0 | F27: =SUMIFS('Daily Input'!$J$6:$J$35,'Daily Input'!$C$6:$C$35,F$6) -> 0 | G27: =SUMIFS('Daily Input'!$J$6:$J$35,'Daily Input'!$C$6:$C$35,G$6) -> 0 | H27: =SUM('Daily Input'!$J$6:$J$35) -> 0
B28: Landing Page Views | C28: =SUMIFS('Daily Input'!$K$6:$K$35,'Daily Input'!$C$6:$C$35,C$6) -> 0 | D28: =SUMIFS('Daily Input'!$K$6:$K$35,'Daily Input'!$C$6:$C$35,D$6) -> 0 | E28: =SUMIFS('Daily Input'!$K$6:$K$35,'Daily Input'!$C$6:$C$35,E$6) -> 0 | F28: =SUMIFS('Daily Input'!$K$6:$K$35,'Daily Input'!$C$6:$C$35,F$6) -> 0 | G28: =SUMIFS('Daily Input'!$K$6:$K$35,'Daily Input'!$C$6:$C$35,G$6) -> 0 | H28: =SUM('Daily Input'!$K$6:$K$35) -> 0
B29: Product Views | C29: =SUMIFS('Daily Input'!$L$6:$L$35,'Daily Input'!$C$6:$C$35,C$6) -> 0 | D29: =SUMIFS('Daily Input'!$L$6:$L$35,'Daily Input'!$C$6:$C$35,D$6) -> 0 | E29: =SUMIFS('Daily Input'!$L$6:$L$35,'Daily Input'!$C$6:$C$35,E$6) -> 0 | F29: =SUMIFS('Daily Input'!$L$6:$L$35,'Daily Input'!$C$6:$C$35,F$6) -> 0 | G29: =SUMIFS('Daily Input'!$L$6:$L$35,'Daily Input'!$C$6:$C$35,G$6) -> 0 | H29: =SUM('Daily Input'!$L$6:$L$35) -> 0
B30: Add to Cart | C30: =SUMIFS('Daily Input'!$M$6:$M$35,'Daily Input'!$C$6:$C$35,C$6) -> 0 | D30: =SUMIFS('Daily Input'!$M$6:$M$35,'Daily Input'!$C$6:$C$35,D$6) -> 0 | E30: =SUMIFS('Daily Input'!$M$6:$M$35,'Daily Input'!$C$6:$C$35,E$6) -> 0 | F30: =SUMIFS('Daily Input'!$M$6:$M$35,'Daily Input'!$C$6:$C$35,F$6) -> 0 | G30: =SUMIFS('Daily Input'!$M$6:$M$35,'Daily Input'!$C$6:$C$35,G$6) -> 0 | H30: =SUM('Daily Input'!$M$6:$M$35) -> 0
B31: Checkout Initiations | C31: =SUMIFS('Daily Input'!$N$6:$N$35,'Daily Input'!$C$6:$C$35,C$6) -> 0 | D31: =SUMIFS('Daily Input'!$N$6:$N$35,'Daily Input'!$C$6:$C$35,D$6) -> 0 | E31: =SUMIFS('Daily Input'!$N$6:$N$35,'Daily Input'!$C$6:$C$35,E$6) -> 0 | F31: =SUMIFS('Daily Input'!$N$6:$N$35,'Daily Input'!$C$6:$C$35,F$6) -> 0 | G31: =SUMIFS('Daily Input'!$N$6:$N$35,'Daily Input'!$C$6:$C$35,G$6) -> 0 | H31: =SUM('Daily Input'!$N$6:$N$35) -> 0
B32: CTR (Link Clicks / Impressions) | C32: =IF(N(C26)=0,"",C27/C26) | D32: =IF(N(D26)=0,"",D27/D26) | E32: =IF(N(E26)=0,"",E27/E26) | F32: =IF(N(F26)=0,"",F27/F26) | G32: =IF(N(G26)=0,"",G27/G26) | H32: =IF(N(H26)=0,"",H27/H26)
B33: CPC (R$) | C33: =IF(N(C27)=0,"",C8/C27) | D33: =IF(N(D27)=0,"",D8/D27) | E33: =IF(N(E27)=0,"",E8/E27) | F33: =IF(N(F27)=0,"",F8/F27) | G33: =IF(N(G27)=0,"",G8/G27) | H33: =IF(N(H27)=0,"",H8/H27)
B34: Cost per Landing Page View (R$) | C34: =IF(N(C28)=0,"",C8/C28) | D34: =IF(N(D28)=0,"",D8/D28) | E34: =IF(N(E28)=0,"",E8/E28) | F34: =IF(N(F28)=0,"",F8/F28) | G34: =IF(N(G28)=0,"",G8/G28) | H34: =IF(N(H28)=0,"",H8/H28)
B35: LPV Rate (LPV / Link Clicks) | C35: =IF(N(C27)=0,"",C28/C27) | D35: =IF(N(D27)=0,"",D28/D27) | E35: =IF(N(E27)=0,"",E28/E27) | F35: =IF(N(F27)=0,"",F28/F27) | G35: =IF(N(G27)=0,"",G28/G27) | H35: =IF(N(H27)=0,"",H28/H27)
B36: Product View Rate (PV / LPV) | C36: =IF(N(C28)=0,"",C29/C28) | D36: =IF(N(D28)=0,"",D29/D28) | E36: =IF(N(E28)=0,"",E29/E28) | F36: =IF(N(F28)=0,"",F29/F28) | G36: =IF(N(G28)=0,"",G29/G28) | H36: =IF(N(H28)=0,"",H29/H28)
B37: ATC Rate (ATC / PV) | C37: =IF(N(C29)=0,"",C30/C29) | D37: =IF(N(D29)=0,"",D30/D29) | E37: =IF(N(E29)=0,"",E30/E29) | F37: =IF(N(F29)=0,"",F30/F29) | G37: =IF(N(G29)=0,"",G30/G29) | H37: =IF(N(H29)=0,"",H30/H29)
B38: Checkout Rate (Checkout / ATC) | C38: =IF(N(C30)=0,"",C31/C30) | D38: =IF(N(D30)=0,"",D31/D30) | E38: =IF(N(E30)=0,"",E31/E30) | F38: =IF(N(F30)=0,"",F31/F30) | G38: =IF(N(G30)=0,"",G31/G30) | H38: =IF(N(H30)=0,"",H31/H30)
B39: Purchase CVR (Fulfilled / Checkout) | C39: =IF(N(C31)=0,"",C13/C31) | D39: =IF(N(D31)=0,"",D13/D31) | E39: =IF(N(E31)=0,"",E13/E31) | F39: =IF(N(F31)=0,"",F13/F31) | G39: =IF(N(G31)=0,"",G13/G31) | H39: =IF(N(H31)=0,"",H13/H31)
B40: Hard-stop conditions logged (count) | C40: =COUNTIFS('Daily Input'!$C$6:$C$35,C$6,'Daily Input'!$V$6:$V$35,"Missing")+COUNTIFS('Daily Input'!$C$6:$C$35,C$6,'Daily Input'!$V$6:$V$35,"Duplicated")+COUNTIFS('Daily Input'!$C$6:$C$35,C$6,'Daily Input'!$V$6:$V$35,"Discrepancy")+COUNTIFS('Daily Input'!$C$6:$C$35,C$6,'Daily Input'!$W$6:$W$35,"Failing")+COUNTIFS('Daily Input'!$C$6:$C$35,C$6,'Daily Input'!$X$6:$X$35,"Out of stock")+COUNTIFS('Daily Input'!$C$6:$C$35,C$6,'Daily Input'!$H$6:$H$35,">"&'Daily Input'!$G$3) -> 0 | D40: =COUNTIFS('Daily Input'!$C$6:$C$35,D$6,'Daily Input'!$V$6:$V$35,"Missing")+COUNTIFS('Daily Input'!$C$6:$C$35,D$6,'Daily Input'!$V$6:$V$35,"Duplicated")+COUNTIFS('Daily Input'!$C$6:$C$35,D$6,'Daily Input'!$V$6:$V$35,"Discrepancy")+COUNTIFS('Daily Input'!$C$6:$C$35,D$6,'Daily Input'!$W$6:$W$35,"Failing")+COUNTIFS('Daily Input'!$C$6:$C$35,D$6,'Daily Input'!$X$6:$X$35,"Out of stock")+COUNTIFS('Daily Input'!$C$6:$C$35,D$6,'Daily Input'!$H$6:$H$35,">"&'Daily Input'!$G$3) -> 0 | E40: =COUNTIFS('Daily Input'!$C$6:$C$35,E$6,'Daily Input'!$V$6:$V$35,"Missing")+COUNTIFS('Daily Input'!$C$6:$C$35,E$6,'Daily Input'!$V$6:$V$35,"Duplicated")+COUNTIFS('Daily Input'!$C$6:$C$35,E$6,'Daily Input'!$V$6:$V$35,"Discrepancy")+COUNTIFS('Daily Input'!$C$6:$C$35,E$6,'Daily Input'!$W$6:$W$35,"Failing")+COUNTIFS('Daily Input'!$C$6:$C$35,E$6,'Daily Input'!$X$6:$X$35,"Out of stock")+COUNTIFS('Daily Input'!$C$6:$C$35,E$6,'Daily Input'!$H$6:$H$35,">"&'Daily Input'!$G$3) -> 0 | F40: =COUNTIFS('Daily Input'!$C$6:$C$35,F$6,'Daily Input'!$V$6:$V$35,"Missing")+COUNTIFS('Daily Input'!$C$6:$C$35,F$6,'Daily Input'!$V$6:$V$35,"Duplicated")+COUNTIFS('Daily Input'!$C$6:$C$35,F$6,'Daily Input'!$V$6:$V$35,"Discrepancy")+COUNTIFS('Daily Input'!$C$6:$C$35,F$6,'Daily Input'!$W$6:$W$35,"Failing")+COUNTIFS('Daily Input'!$C$6:$C$35,F$6,'Daily Input'!$X$6:$X$35,"Out of stock")+COUNTIFS('Daily Input'!$C$6:$C$35,F$6,'Daily Input'!$H$6:$H$35,">"&'Daily Input'!$G$3) -> 0 | G40: =COUNTIFS('Daily Input'!$C$6:$C$35,G$6,'Daily Input'!$V$6:$V$35,"Missing")+COUNTIFS('Daily Input'!$C$6:$C$35,G$6,'Daily Input'!$V$6:$V$35,"Duplicated")+COUNTIFS('Daily Input'!$C$6:$C$35,G$6,'Daily Input'!$V$6:$V$35,"Discrepancy")+COUNTIFS('Daily Input'!$C$6:$C$35,G$6,'Daily Input'!$W$6:$W$35,"Failing")+COUNTIFS('Daily Input'!$C$6:$C$35,G$6,'Daily Input'!$X$6:$X$35,"Out of stock")+COUNTIFS('Daily Input'!$C$6:$C$35,G$6,'Daily Input'!$H$6:$H$35,">"&'Daily Input'!$G$3) -> 0 | H40: =SUM(C40:G40) -> 0
B41: Largest Funnel Bottleneck | C41: =IFERROR(CHOOSE(MATCH(MIN(C35:C39),C35:C39,0),"Click → Landing Page View","Landing Page View → Product View","Product View → Add to Cart","Add to Cart → Checkout","Checkout → Purchase"),"N/A") -> N/A | D41: =IFERROR(CHOOSE(MATCH(MIN(D35:D39),D35:D39,0),"Click → Landing Page View","Landing Page View → Product View","Product View → Add to Cart","Add to Cart → Checkout","Checkout → Purchase"),"N/A") -> N/A | E41: =IFERROR(CHOOSE(MATCH(MIN(E35:E39),E35:E39,0),"Click → Landing Page View","Landing Page View → Product View","Product View → Add to Cart","Add to Cart → Checkout","Checkout → Purchase"),"N/A") -> N/A | F41: =IFERROR(CHOOSE(MATCH(MIN(F35:F39),F35:F39,0),"Click → Landing Page View","Landing Page View → Product View","Product View → Add to Cart","Add to Cart → Checkout","Checkout → Purchase"),"N/A") -> N/A | G41: =IFERROR(CHOOSE(MATCH(MIN(G35:G39),G35:G39,0),"Click → Landing Page View","Landing Page View → Product View","Product View → Add to Cart","Add to Cart → Checkout","Checkout → Purchase"),"N/A") -> N/A | H41: =IFERROR(CHOOSE(MATCH(MIN(H35:H39),H35:H39,0),"Click → Landing Page View","Landing Page View → Product View","Product View → Add to Cart","Add to Cart → Checkout","Checkout → Purchase"),"N/A") -> N/A
B42: Diagnostic Flag (heuristic, not proof) | C42: =IF(AND(N(C28)>=50,N(C30)=0),"50+ LPVs, 0 ATC — revise product, offer, message or landing match",IF(AND(N(C30)>=10,N(C31)=0),"10+ ATCs, 0 checkout — inspect cart, shipping and checkout friction",IF(AND(N(C31)>=5,N(C13)=0),"5+ checkouts, 0 purchase — inspect payment, final price, delivery and trust",IF(N(C8)=0,"No data","No diagnostic threshold breached")))) -> No data | D42: =IF(AND(N(D28)>=50,N(D30)=0),"50+ LPVs, 0 ATC — revise product, offer, message or landing match",IF(AND(N(D30)>=10,N(D31)=0),"10+ ATCs, 0 checkout — inspect cart, shipping and checkout friction",IF(AND(N(D31)>=5,N(D13)=0),"5+ checkouts, 0 purchase — inspect payment, final price, delivery and trust",IF(N(D8)=0,"No data","No diagnostic threshold breached")))) -> No data | E42: =IF(AND(N(E28)>=50,N(E30)=0),"50+ LPVs, 0 ATC — revise product, offer, message or landing match",IF(AND(N(E30)>=10,N(E31)=0),"10+ ATCs, 0 checkout — inspect cart, shipping and checkout friction",IF(AND(N(E31)>=5,N(E13)=0),"5+ checkouts, 0 purchase — inspect payment, final price, delivery and trust",IF(N(E8)=0,"No data","No diagnostic threshold breached")))) -> No data | F42: =IF(AND(N(F28)>=50,N(F30)=0),"50+ LPVs, 0 ATC — revise product, offer, message or landing match",IF(AND(N(F30)>=10,N(F31)=0),"10+ ATCs, 0 checkout — inspect cart, shipping and checkout friction",IF(AND(N(F31)>=5,N(F13)=0),"5+ checkouts, 0 purchase — inspect payment, final price, delivery and trust",IF(N(F8)=0,"No data","No diagnostic threshold breached")))) -> No data | G42: =IF(AND(N(G28)>=50,N(G30)=0),"50+ LPVs, 0 ATC — revise product, offer, message or landing match",IF(AND(N(G30)>=10,N(G31)=0),"10+ ATCs, 0 checkout — inspect cart, shipping and checkout friction",IF(AND(N(G31)>=5,N(G13)=0),"5+ checkouts, 0 purchase — inspect payment, final price, delivery and trust",IF(N(G8)=0,"No data","No diagnostic threshold breached")))) -> No data | H42: =IF(AND(N(H28)>=50,N(H30)=0),"50+ LPVs, 0 ATC — revise product, offer, message or landing match",IF(AND(N(H30)>=10,N(H31)=0),"10+ ATCs, 0 checkout — inspect cart, shipping and checkout friction",IF(AND(N(H31)>=5,N(H13)=0),"5+ checkouts, 0 purchase — inspect payment, final price, delivery and trust",IF(N(H8)=0,"No data","No diagnostic threshold breached")))) -> No data
...

Sheet Six-Month Reinvestment
B2: Six-Month Reinvestment Loop
B3: Source plan: MQ-REV-01 — 30-Day Revenue and Six-Month Reinvestment Plan
B4: P(t) = (R(t) × m) − A(t) − X(t). If P(t) < 0 the automatic reinvestment loop stops. Otherwise the next available budget A(t+1) = A(t) + P(t) — recovered advertising principal plus verified marketing profit only.
B5: ASSUMPTIONS — edit the blue cells only
B6: Opening advertising principal (R$) | C6: 600 | D6: ← Approved seed capital: R$20/day × 30 days
B7: Contribution margin (m) | C7: 0.1 | D7: ← Stated margin; INTELLIGENCE GAP: cost basis unverified
B8: Default excluded variable costs per month, X (R$) | C8: 0
B9: Month 1 settled attributed revenue observed in tracker (R$) | C9: ='Weekly Summary'!$H$11 -> 0 | D9: ← Live link to Weekly Summary Month Total
B10: Months without an entered Actual Settled Revenue are projected at the Expected ROAS assumption — illustrative arithmetic, not a forecast. Enter actual settled revenue as each month closes; it always overrides the projection.
B12: REINVESTMENT LOOP — MONTHS 1 TO 6
B13: Month | C13: Advertising Principal A(t) (R$) | D13: Expected ROAS (x) | E13: Actual Settled Revenue (R$) | F13: Revenue Used (R$) | G13: Contribution (R$) | H13: Excluded Variable Costs X (R$) | I13: Marketing Profit P(t) (R$) | J13: Next Available Budget A(t+1) (R$) | K13: Reinvestment Status
B14: Month 1 | C14: =$C$6 -> 600 | D14: 10 | E14: =IF(N($C$9)=0,"",$C$9) | F14: =IF(C14="","",IF(N(E14)=0,C14*N(D14),E14)) -> 6000 | G14: =IF(F14="","",F14*$C$7) -> 600 | H14: =$C$8 -> 0 | I14: =IF(F14="","",G14-C14-N(H14)) -> 0 | J14: =IF(I14="","",IF(I14<0,"",C14+I14)) -> 600 | K14: =IF(I14="","HOLD — no budget available",IF(I14<0,"STOP — automatic reinvestment halted",IF(I14=0,"HOLD — principal preserved, no profit to reinvest","REINVEST — release verified profit"))) -> HOLD — principal preserved, no profit to reinvest
B15: Month 2 | C15: =IF(J14="","",J14) -> 600 | D15: 10 | F15: =IF(C15="","",IF(N(E15)=0,C15*N(D15),E15)) -> 6000 | G15: =IF(F15="","",F15*$C$7) -> 600 | H15: =$C$8 -> 0 | I15: =IF(F15="","",G15-C15-N(H15)) -> 0 | J15: =IF(I15="","",IF(I15<0,"",C15+I15)) -> 600 | K15: =IF(I15="","HOLD — no budget available",IF(I15<0,"STOP — automatic reinvestment halted",IF(I15=0,"HOLD — principal preserved, no profit to reinvest","REINVEST — release verified profit"))) -> HOLD — principal preserved, no profit to reinvest
B16: Month 3 | C16: =IF(J15="","",J15) -> 600 | D16: 10 | F16: =IF(C16="","",IF(N(E16)=0,C16*N(D16),E16)) -> 6000 | G16: =IF(F16="","",F16*$C$7) -> 600 | H16: =$C$8 -> 0 | I16: =IF(F16="","",G16-C16-N(H16)) -> 0 | J16: =IF(I16="","",IF(I16<0,"",C16+I16)) -> 600 | K16: =IF(I16="","HOLD — no budget available",IF(I16<0,"STOP — automatic reinvestment halted",IF(I16=0,"HOLD — principal preserved, no profit to reinvest","REINVEST — release verified profit"))) -> HOLD — principal preserved, no profit to reinvest
B17: Month 4 | C17: =IF(J16="","",J16) -> 600 | D17: 10 | F17: =IF(C17="","",IF(N(E17)=0,C17*N(D17),E17)) -> 6000 | G17: =IF(F17="","",F17*$C$7) -> 600 | H17: =$C$8 -> 0 | I17: =IF(F17="","",G17-C17-N(H17)) -> 0 | J17: =IF(I17="","",IF(I17<0,"",C17+I17)) -> 600 | K17: =IF(I17="","HOLD — no budget available",IF(I17<0,"STOP — automatic reinvestment halted",IF(I17=0,"HOLD — principal preserved, no profit to reinvest","REINVEST — release verified profit"))) -> HOLD — principal preserved, no profit to reinvest
B18: Month 5 | C18: =IF(J17="","",J17) -> 600 | D18: 10 | F18: =IF(C18="","",IF(N(E18)=0,C18*N(D18),E18)) -> 6000 | G18: =IF(F18="","",F18*$C$7) -> 600 | H18: =$C$8 -> 0 | I18: =IF(F18="","",G18-C18-N(H18)) -> 0 | J18: =IF(I18="","",IF(I18<0,"",C18+I18)) -> 600 | K18: =IF(I18="","HOLD — no budget available",IF(I18<0,"STOP — automatic reinvestment halted",IF(I18=0,"HOLD — principal preserved, no profit to reinvest","REINVEST — release verified profit"))) -> HOLD — principal preserved, no profit to reinvest
B19: Month 6 | C19: =IF(J18="","",J18) -> 600 | D19: 10 | F19: =IF(C19="","",IF(N(E19)=0,C19*N(D19),E19)) -> 6000 | G19: =IF(F19="","",F19*$C$7) -> 600 | H19: =$C$8 -> 0 | I19: =IF(F19="","",G19-C19-N(H19)) -> 0 | J19: =IF(I19="","",IF(I19<0,"",C19+I19)) -> 600 | K19: =IF(I19="","HOLD — no budget available",IF(I19<0,"STOP — automatic reinvestment halted",IF(I19=0,"HOLD — principal preserved, no profit to reinvest","REINVEST — release verified profit"))) -> HOLD — principal preserved, no profit to reinvest
B20: Cumulative (Months 1–6) | C20: =SUM(C14:C19) -> 3600 | F20: =SUM(F14:F19) -> 36000 | G20: =SUM(G14:G19) -> 3600 | H20: =SUM(H14:H19) -> 0 | I20: =SUM(I14:I19) -> 0
B21: Available advertising budget after Month 6 (R$) | C21: =IF(J19="","N/A",J19) -> 600 | D21: Release only after orders settle and refunds, chargebacks, taxes, fees, fulfilment and shipping are reserved.
B24: ILLUSTRATIVE ROAS SCENARIOS — ARITHMETIC, NOT FORECASTS
B25: Assumes a constant contribution margin, no excluded variable costs, no settlement delay, and full reinvestment of recovered principal plus verified profit. These are not predictions of Zupp1 results.
B26: Available advertising spend | C26: Scenario A | D26: Scenario B | E26: Scenario C
B27: Scenario ROAS (x) | C27: 8 | D27: 10 | E27: 12
B28: Month 1 available spend (R$) | C28: =$C$6 -> 600 | D28: =$C$6 -> 600 | E28: =$C$6 -> 600
B29: Month 2 available spend (R$) | C29: =IF(ISNUMBER(C28),IF(C28*C$27*$C$7-C28<0,"STOP",C28+(C28*C$27*$C$7-C28)),"STOP") -> STOP | D29: =IF(ISNUMBER(D28),IF(D28*D$27*$C$7-D28<0,"STOP",D28+(D28*D$27*$C$7-D28)),"STOP") -> 600 | E29: =IF(ISNUMBER(E28),IF(E28*E$27*$C$7-E28<0,"STOP",E28+(E28*E$27*$C$7-E28)),"STOP") -> 720
B30: Month 3 available spend (R$) | C30: =IF(ISNUMBER(C29),IF(C29*C$27*$C$7-C29<0,"STOP",C29+(C29*C$27*$C$7-C29)),"STOP") -> STOP | D30: =IF(ISNUMBER(D29),IF(D29*D$27*$C$7-D29<0,"STOP",D29+(D29*D$27*$C$7-D29)),"STOP") -> 600 | E30: =IF(ISNUMBER(E29),IF(E29*E$27*$C$7-E29<0,"STOP",E29+(E29*E$27*$C$7-E29)),"STOP") -> 864
B31: Month 4 available spend (R$) | C31: =IF(ISNUMBER(C30),IF(C30*C$27*$C$7-C30<0,"STOP",C30+(C30*C$27*$C$7-C30)),"STOP") -> STOP | D31: =IF(ISNUMBER(D30),IF(D30*D$27*$C$7-D30<0,"STOP",D30+(D30*D$27*$C$7-D30)),"STOP") -> 600 | E31: =IF(ISNUMBER(E30),IF(E30*E$27*$C$7-E30<0,"STOP",E30+(E30*E$27*$C$7-E30)),"STOP") -> 1036.8
B32: Month 5 available spend (R$) | C32: =IF(ISNUMBER(C31),IF(C31*C$27*$C$7-C31<0,"STOP",C31+(C31*C$27*$C$7-C31)),"STOP") -> STOP | D32: =IF(ISNUMBER(D31),IF(D31*D$27*$C$7-D31<0,"STOP",D31+(D31*D$27*$C$7-D31)),"STOP") -> 600 | E32: =IF(ISNUMBER(E31),IF(E31*E$27*$C$7-E31<0,"STOP",E31+(E31*E$27*$C$7-E31)),"STOP") -> 1244.16
B33: Month 6 available spend (R$) | C33: =IF(ISNUMBER(C32),IF(C32*C$27*$C$7-C32<0,"STOP",C32+(C32*C$27*$C$7-C32)),"STOP") -> STOP | D33: =IF(ISNUMBER(D32),IF(D32*D$27*$C$7-D32<0,"STOP",D32+(D32*D$27*$C$7-D32)),"STOP") -> 600 | E33: =IF(ISNUMBER(E32),IF(E32*E$27*$C$7-E32<0,"STOP",E32+(E32*E$27*$C$7-E32)),"STOP") -> 1492.992
B34: Available advertising spend after Month 6 (R$) | C34: =IF(ISNUMBER(C33),IF(C33*C$27*$C$7-C33<0,"STOP",C33+(C33*C$27*$C$7-C33)),"STOP") -> STOP | D34: =IF(ISNUMBER(D33),IF(D33*D$27*$C$7-D33<0,"STOP",D33+(D33*D$27*$C$7-D33)),"STOP") -> 600 | E34: =IF(ISNUMBER(E33),IF(E33*E$27*$C$7-E33<0,"STOP",E33+(E33*E$27*$C$7-E33)),"STOP") -> 1791.5904
B36: Reading: at 8.0x the first month loses money and the automatic loop stops; at 10.0x the loop merely preserves the original advertising principal; at 12.0x it compounds slowly. Any excluded variable cost pushes true break-even above 10.0x.

Sheet Definitions & Rules
B2: Definitions, Evidence Labels and Operating Rules
B3: Source plan: MQ-REV-01 — 30-Day Revenue and Six-Month Reinvestment Plan · Prepared for USS Zupp1 · Geography: São Paulo state
B5: METRIC DEFINITIONS
B6: Settled attributed revenue | C6: Paid and fulfilled revenue attributed to the campaign, less cancellations and refunds. Platform-reported revenue alone is not settled revenue.
B7: Contribution (R$) | C7: Settled attributed revenue × verified product contribution margin. The money that exists before advertising.
B8: Marketing profit P | C8: P = (R × m) − A − X: contribution minus ad spend minus excluded variable costs. Reinvestment is permitted only when P is positive.
B9: Blended ROAS | C9: Settled attributed revenue ÷ ad spend. Break-even is 1 ÷ contribution margin = 10.0x at a 10% margin, before excluded variable costs.
B10: CPA | C10: Ad spend ÷ attributed fulfilled customers.
B11: Maximum allowable CAC | C11: AOV × verified contribution margin. The hard economic ceiling for acquisition cost.
B12: AOV | C12: Settled attributed revenue ÷ fulfilled attributed orders, computed from period totals, never as an average of daily averages.
B13: Reinvestment wallet | C13: Recovered advertising principal plus verified marketing profit only. Never unsettled revenue, expected refunds or supplier obligations.
B14: Excluded variable costs X | C14: Refunds, chargebacks, discounts, shipping subsidies, payment fees and taxes not already inside the stated margin.
B15: Diagnostic metrics | C15: CTR, CPC, LPV rate, product-view rate, ATC rate, checkout rate and purchase CVR diagnose delivery and message resonance. They never override contribution, CPA and settled marketing profit.
B16: EVIDENCE LABELS
B17: FACT | C17: Directly observed in platform, analytics, order, payment or support records.
B18: ASSESSMENT | C18: Interpretation of observed evidence.
B19: RECOMMENDATION | C19: Proposed action based on facts and assessments.
B20: INTELLIGENCE GAP | C20: A value or causal explanation that cannot yet be verified. Label results below the diagnostic thresholds as INTELLIGENCE GAP — insufficient observations rather than declaring a winner or loser.
B21: IMMEDIATE HARD STOPS — pause spending at once
B22: Tracking integrity | C22: Purchase tracking missing, duplicated or materially inconsistent with WooCommerce.
B23: Checkout or payment | C23: Checkout or payment is failing.
B24: Fulfilment | C24: Advertised product unavailable or its fulfilment promise unreliable.
B25: Disclosure accuracy | C25: Displayed price, shipping, promotion, return policy or disclosure is inaccurate.
B26: Budget breach | C26: Spend exceeds the approved daily (R$20) or monthly (R$600) ceiling.
B27: Customer harm / policy | C27: Customer harm, misleading messaging or policy risk detected.
B28: ECONOMIC STOPS
B29: Campaign stop | C29: Stop paid acquisition if cumulative spend reaches R$600 without a fulfilled attributed sale.
B30: Path stop | C30: Stop a product-audience-message path without a sale when spend reaches the lower of the weekly ceiling or the greater of R$40 and 2× the verified maximum allowable CAC. Strong checkout evidence may justify one additional controlled interval, documented before spending it.
